Workbook

Sheet Matriz Ckeck LIst
B3: MATRIZ PARA COMPROBACIÓN REQUERIMIENTOS DE CALIDAD DE PROYECTO ACADÉMICO
B5: SISTEMA: | E5: Sistema de planificación y seguimiento de eventos sociales y deportivos del Club de Suboficiales Retirados (EVENTUAL)
B6: Requerimientos Funcionales
B7: Nº | C7: CRITERIOS DE CALIDAD (Documento/Requerimientos) | E7: Status Nivel de Acuerdo | F7: CU-006: Registrar Gastos del Evento | G7: Status Nivel de Acuerdo | H7: CU-007: Registrar Aportes Económicos | I7: Status Nivel de Acuerdo | J7: CU-008 Registrar Evento | K7: Status Nivel de Acuerdo | L7: CU-009 Difundir Información del Evento | M7: Status Nivel de Acuerdo | N7: CU-010 Ingresar Proveedor
B10: 1 | C10: Agreed | E10: OK | F10: 1. Videoconferencia de la entrevista 2. Es una necesidad estándar y aceptada por los stakeholders para el control financiero del club. 3. Aceptación por videoconferencia | G10: OK | H10: 1. Videoconferencia de la entrevista 2. Minuta de la entrevista 3. Aceptación por videoconferencia | I10: OK | J10: 1. Videoconferencia de la entrevista 2. Minuta de la entrevista 3. Aceptación por videoconferencia | K10: OK | L10: 1. Videoconferencia de la entrevista 2. Minuta de la entrevista 3. Aceptación por videoconferencia | M10: OK | N10: 1. Videoconferencia de la entrevista 2. Minuta de la entrevista 3. Aceptación por videoconferencia
B11: 2 | C11: Ranked | E11: OK | F11: 1. Tiene una prioridad alta/esencial, ya que el flujo de caja requiere un soporte de emisión inmediata. | G11: OK | H11: 1. Tiene una prioridad alta bien definida, ya que el sistema necesita registrar de dónde entra el dinero antes de poder ejecutar los eventos. | I11: OK | J11: 1. Tiene asignada prioridad Alta, lo que indica que fue ponderado por importancia dentro del sistema. | K11: OK | L11: 1. Tiene prioridad Alta asignada, lo que indica que fue ponderado en función de su importancia dentro del flujo del sistemas. | M11: OK | N11: 1. Tiene prioridad Media asignada, lo que indica que fue ponderado y ubicado en un nivel de importancia menor respecto a otros casos de uso del sistema.
B12: 3 | C12: Unambiguos | E12: OK | F12: 1. Los pasos del flujo básico ("Ingresar datos", "Validar información", "Guardar en BD") son directos y usan la terminología estándar del negocio. | G12: OK | H12: 1. El flujo describe de forma directa los pasos que realiza el Tesorero y la respuesta del sistema sin dobles interpretaciones. | I12: NOK | J12: 1. La mayoría de los pasos son claros, pero el paso 10 indica "programa notificaciones según el cronograma definido" sin especificar cuál cronograma ni en qué momento exacto, lo que puede tener más de una interpretación. | K12: NOK | L12: 1. El paso 9 menciona "seleccionando uno o más tiempos de aviso disponibles (por ejemplo: 15 días, 7 días o 1 día)" usando "por ejemplo", lo que deja abierto si esos son los únicos valores posibles o si hay más.s. | M12: NOK | N12: 1. El paso 8 indica que el Secretario "asigna una calificación inicial al proveedor" sin especificar la escala (¿del 1 al 5? ¿del 1 al 10?), ni los criterios para asignarla. Esto puede interpretarse de distintas maneras por distintos lectores..
B13: 4 | C13: Valid and up-to date | E13: OK | F13: 1. Está vigente y alineado con la última estructura del alcance del sistema planteada en el documento. | G13: OK | H13: 1. Es totalmente vigente y coherente con el alcance actual del módulo de gestión de eventos y finanzas del club. | I13: OK | J13: 1. El caso de uso incluye referencias a casos de uso relacionados como "Definir Evento", lo que muestra que está articulado con el estado actual del sistema.. | K13: OK | L13: 1. El caso de uso referencia correctamente el estado previo del evento ("Registrado y definido"). | M13: OK | N13: 1. está alineado con el estado actual del sistema, siendo referenciado correctamente por CU-009 Consultar Proveedores como precondición.
B14: 5 | C14: Correct | E14: OK | F14: 1. Se describe clarmente el proceso real que un organizador debe seguir para asentar un gasto en la aplicación. | G14: OK | H14: 1. Describe de forma precisa la secuencia real para asentar un ingreso. | I14: OK | J14: 1. Refleja correctamente las expectativas del Presidente como actor: confirmar datos, cargar documentos, registrar el evento y habilitarlo para difusión. | K14: OK | L14: 1. Refleja adecuadamente las expectativas del Secretario: personalizar mensaje, seleccionar canales, programar envío y configurar recordatorios.. | M14: NOK | N14: 1. El flujo general refleja las expectativas del Secretario, pero la descripción del caso de uso nivel 0 menciona que el propósito es registrar "proveedores de servicios relacionados con viajes terrestres", lo que es inconsistente con los campos del formulario que incluyen categorías como alimentación, sonido y decoración, que van mucho más allá de viajes terrestres.
B15: 6 | C15: Consistent | E15: OK | F15: 1. No entra en contradicción con ningún otro caso de uso ni con el modelo de dominio; depende de la existencia previa de la entidad "Evento" | G15: OK | H15: 1. Aquí hay un choque de consistencia global: en el CU-001 registras "Miembros" y en el CU-005 manejas "Pagos" (Efectivo/Transferencia) ligados a matrículas. Sin embargo, en este CU-007, el flujo no aclara si el aporte lo hace un "Miembro" ya registrado en el sistema, ni si usa los mismos métodos de pago del CU-005, generando una ruptura en la lógica de las entidades del documento. | I15: OK | J15: 1. No contradice otros casos de uso. Está correctamente enlazado con "Definir Evento" como precondición y con "Difundir Evento" como postcondición. | K15: OK | L15: 1. No contradice otros casos de uso. Requiere correctamente que el evento esté en estado "Registrado" (postcondición del CU-008) y al finalizar cambia el estado a "Difundido", lo que habilita el CU de Confirmar Asistencia. | M15: NOK | N15: 1. Existe una contradicción directa: la descripción del caso de uso dice "proveedores de servicios relacionados con viajes terrestres", pero en el formulario y en CU-009 Consultar Proveedores se manejan categorías como alimentación, sonido y decoración.
B16: 7 | C16: Verifiable | E16: OK | F16: 1. Es totalmente medible a través de pruebas de caja negra: se ejecutan los pasos del caso de uso y se comprueba si el gasto se almacena o si fallan las validaciones. | G16: OK | H16: 1. Se puede verificar ejecutando el flujo y revisando el impacto en la base de datos.. | I16: OK | J16: 1. Las acciones son comprobables: se genera un código EVT-YYYY-NNN único, el estado cambia a "Registrado" y se habilita "Difundir Evento". Estas son condiciones objetivas que pueden probarse en el softwarel. | K16: OK | L16: 1. Las postcondiciones son comprobables: el evento cambia a estado "Difundido", las notificaciones quedan registradas y los recordatorios son programados. | M16: OK | N16: 1. El proveedor queda registrado y disponible para consulta. El sistema muestra un mensaje de confirmación de registro exitoso, lo que permite verificar objetivamente si el caso de uso se ejecutó correctamente..
B17: 8 | C17: Realizable | E17: OK | F17: 1. El flujo planteado es técnicamente viable de programar con la arquitectura full-stack (Flutter/Node.js) definida para el proyecto. | G17: OK | H17: 1. Es totalmente programable dentro de la arquitectura de software planteada. | I17: OK | J17: 1. Las funcionalidades descritas (validar formatos, generar código único, cambiar estado, programar notificaciones) son técnicamente implementables en una aplicación móvil con backend. | K17: OK | L17: 1. El envío por WhatsApp y app, la programación de recordatorios y el uso de plantillas personalizables son funcionalidades implementables con las tecnologías actuales disponibles para el proyecto. | M17: OK | N17: 1. El registro de un proveedor con los campos descritos es completamente implementable con las tecnologías del proyecto.
B18: 9 | C18: Traceable | E18: OK | F18: 1.Está perfectamente identificado en el índice del documento, asociado a sus respectivos diagramas y entidades del sistema. | G18: OK | H18: 1. Se vincula con los objetivos del sistema y el modelo de dominio. | I18: NOK | J18: 1. No existe un vínculo a los casos de uso que deberia tener relacion(NF-04, NF-05). | K18: NOK | L18: 1. No se enlaza explícitamente con requerimientos no funcionales relacionados como NF-03 (baja conectividad) o NF-06 (rendimiento), que afectan directamente el envío masivo de notificaciones. | M18: NOK | N18: 1. No tiene un identificador de trazabilidad que permita rastrear su relación con otros casos de uso que lo usan como precondición, como CU-011 Registrar Cotizaciones.
B19: 10 | C19: Complete | E19: NOK | F19: 1. No se especifica qué tipos de datos se digitan (ej. formato del monto), si las categorías son una lista fija o texto libre, ni detalla el comportamiento exacto de los mensajes de error en los flujos alternos. | G19: NOK | H19: No especifica: 1. Si el aporte económico altera el presupuesto total del evento definido en la planificación. 2. Si se debe emitir un comprobante digital (como analizamos que falta en otros flujos de pago). 3. Cómo se maneja el flujo alterno si el aporte supera el límite requerido para el evento. | I19: NOK | J19: 1. Faltan escenarios relevantes: no se documenta qué ocurre si el Presidente intenta registrar un evento sin que el tesorero haya evaluado costos, no hay excepción para documentos duplicados. | K19: NOK | L19: 1. No se documenta qué ocurre si un socio no tiene WhatsApp configurado, no hay excepción para cuando la plantilla institucional no carga correctamente. | M19: NOK | N19: 1. Faltan varios escenarios importantes: no se especifica qué campos son obligatorios y cuáles opcionales en el formulario, no hay excepción para formato de email inválido, no se define el formato o rango válido de la calificación.
B20: 11 | C20: Understandability | E20: OK | F20: 1. Se involucra al único q hara eso (Tesorero) 2. Existe glosario de términos. 3. El elemento cuenta con su nomenclatura formal única indexada como CU-006. | G20: OK | H20: 1. Se involucra al Tesoro que será el único que tendrá acceso a realizar esta acción. 2. Existe glosario de términos | I20: OK | J20: 1. Se involucra al Presidente. 2. Existe glosario de términos. | K20: OK | L20: 1. Se involucra al Secretario, encargado de realizar la las acciones. 2. Existe glosario de términos. | M20: OK | N20: 1. Se involucra al Secretario. 2. Existe glosario de términos.

Sheet Matriz Ckeck LIst CU Finales
B3: MATRIZ PARA COMPROBACIÓN REQUERIMIENTOS DE CALIDAD DE PROYECTO ACADÉMICO
B5: SISTEMA: | E5: Sistema de planificación y seguimiento de eventos sociales y deportivos del Club de Suboficiales Retirados (EVENTUAL)
B6: Requerimientos Funcionales
B7: Nº | C7: CRITERIOS DE CALIDAD (Documento/Requerimientos) | E7: Status Nivel de Acuerdo | F7: RF11 Definir Evento | M7: Status Nivel de Acuerdo | N7: RF12 Ejecutar Evento | Q7: Status Nivel de Acuerdo | R7: RF13 Generar reportes
F9: CU-11-1 Programar evento | H9: CU-11-2 Consultar proveedores | J9: CU-11-3 Registrar cotizaciones | L9: CU-11-4 Evaluar costos | N9: CU-12-1 Registrar asistencia | P9: CU-12-2 Cerrar evento | R9: CU-13-1 Reporte Participación de Socios | T9: CU-13-2 Reporte Historial de eventos | V9: CU-13-3 Reporte Liquidaciones
B10: 1 | C10: Agreed | E10: OK | F10: 1. Videoconferencia de la entrevista 2. Es una necesidad estándar y aceptada por los stakeholders para el control financiero del club. 3. Aceptación por videoconferencia | G10: OK | H10: 1. Videoconferencia de la entrevista 2. Es una necesidad estándar y aceptada por los stakeholders para el control financiero del club. 3. Aceptación por videoconferencia | I10: OK | J10: 1. Videoconferencia de la entrevista 2. Es una necesidad estándar y aceptada por los stakeholders para el control financiero del club. 3. Aceptación por videoconferencia | K10: OK | L10: 1. Videoconferencia de la entrevista 2. Es una necesidad estándar y aceptada por los stakeholders para el control financiero del club. 3. Aceptación por videoconferencia | M10: OK | N10: 1. Videoconferencia de la entrevista 2. Es una necesidad estándar y aceptada por los stakeholders para el control financiero del club. 3. Aceptación por videoconferencia | O10: OK | P10: 1. Videoconferencia de la entrevista 2. Es una necesidad estándar y aceptada por los stakeholders para el control financiero del club. 3. Aceptación por videoconferencia | Q10: OK | R10: 1. Videoconferencia de la entrevista 2. Minuta de la entrevista 3. Aceptación por videoconferencia | S10: OK | T10: 1. Videoconferencia de la entrevista 2. Minuta de la entrevista 3. Aceptación por videoconferencia | U10: OK | V10: 1. Videoconferencia de la entrevista 2. Minuta de la entrevista 3. Aceptación por videoconferencia
B11: 2 | C11: Ranked | E11: OK | F11: 1. Prioridad Alta asignada. 2. Sin programar el evento no pueden ejecutarse los demás casos de uso del módulo. | G11: OK | H11: 1. Prioridad Alta asignada. 2. Es paso previo obligatorio para registrar cotizaciones y evaluar costos. | I11: OK | J11: 1. Prioridad Alta asignada. 2. Apoya la toma de decisiones financieras antes de ejecutar el evento. | K11: OK | L11: 1. Prioridad Alta asignada. 2. Sin cotizaciones registradas, el caso de uso Evaluar Costos no puede ejecutarse. | M11: OK | N11: 1. Prioridad Media asignada. 2. Ocurre en una etapa avanzada del flujo, con menor urgencia sistémica que los requisitos de planificación. | O11: OK | P11: 1. Prioridad Media asignada. 2. Es el paso final del ciclo del evento; su importancia es operativa y de trazabilidad. | Q11: OK | R11: 1. En la descripción del caso de Uso se especifica la prioridad Alta | S11: NOK | T11: 1. La prioridad esta declarada como "media", y al ser la asignación del rol, deberia estar como alta, pues al asignar el rol, se define los accesos del usuario. | U11: OK | V11: Prioridad declarada como "Media", algo correcto ya que editar la información de un socio es algo ocasional.
B12: 3 | C12: Unambiguos | E12: OK | F12: 1. Cada acción del Presidente (seleccionar, definir fecha/hora/ubicación, confirmar) y del sistema (verificar conflictos, registrar, cambiar estado) tiene una sola lectura posible. | G12: OK | H12: 1. El flujo describe con precisión qué hace el usuario (filtrar, seleccionar, marcar candidatos) y qué responde el sistema. Los filtros por tipo de servicio y ubicación son suficientemente concretos. | I12: NOK | J12: 1. El paso 9 indica que el usuario marca cotizaciones como "preferidas", pero el paso 10 solo describe qué ocurre si se escogen varias. No se especifica qué pasa si se marca una sola. 2. El semáforo visual del paso 14 no aclara si se muestra siempre o solo al seleccionar preferidas. | K12: OK | L12: 1. El flujo del Tesorero es directo: accede, selecciona, completa el formulario y confirma. 2. Las validaciones (campos completos, monto positivo, fecha posterior a la actual) están descritas sin doble interpretación. | M12: OK | N12: 1. Los dos métodos de registro (QR y manual) están diferenciados con claridad y sus pasos no se superponen. 2. Las acciones del sistema en cada caso tienen una única interpretación. | O12: OK | P12: 1. El flujo es secuencial y claro. Las validaciones previas al cierre están bien definidas y no generan ambigüedad. | Q12: OK | R12: 1. Redacción en lenguaje claro. 2. El tutor y el equipo interpretan de igual manera el caso de uso | S12: OK | T12: 1. Tiene una redacción en un lenguje claro | U12: OK | V12: Describe la acción de actualizar datos existentes.
B13: 4 | C13: Valid and up-to date | E13: OK | F13: 1. Referencia correctamente "CU Proponer Evento" como precondición. 2. El estado resultante "Definido" es coherente con los demás flujos del módulo. | G13: OK | H13: 1. Referencia el módulo "Definir Evento" y el estado "Registrado y Definido" del evento como precondición. 2. Es coherente con el alcance actual del sistema. | I13: OK | J13: 1. Referencia correctamente "Registrar Cotizaciones" como caso de uso incluido y "Consultar Proveedores" como extensión posible. 2. Está alineado con el estado actual del sistema. | K13: OK | L13: 1. Referencia el módulo "Definir Evento" y el estado previo del evento. 2. El resultado alimenta directamente "Evaluar Costos", lo que mantiene la coherencia del sistema. | M13: OK | N13: 1. Referencia "CU-005 Confirmar Asistencia" y el estado "Difundido" del evento. 2. Está articulado con el estado actual del sistema. | O13: OK | P13: 1. Referencia el estado previo "En ejecución" y el efecto habilitador sobre la liquidación. 2. Alineado con los demás flujos del módulo. | Q13: OK | R13: 1. Toda nueva información ha sido incorporada, se han incorporado los últimos cambios pedidos luego del feedback realizado por el cliente | S13: OK | T13: 1. Toda nueva información ha sido incorporada, se han incorporado los últimos cambios pedidos luego del feedback realizado por el cliente | U13: OK | V13: 1. Toda nueva información ha sido incorporada, se han incorporado los últimos cambios pedidos luego del feedback realizado por el cliente
B14: 5 | C14: Correct | E14: OK | F14: 1. Refleja las expectativas del Presidente: revisar propuestas, aprobar o rechazar, y definir los datos definitivos del evento. 2. El flujo coincide con la realidad operativa descrita en la entrevista. | G14: OK | H14: 1. Refleja las expectativas de ambos actores: explorar el catálogo de proveedores, filtrar, revisar perfiles y marcar candidatos. 2. Coincide con lo descrito en la entrevista. | I14: OK | J14: 1. Refleja lo que el Presidente y el Tesorero esperan: comparar cotizaciones, ver un cuadro comparativo con semáforo y elegir la opción más conveniente. | K14: OK | L14: 1. Describe con precisión la secuencia real del Tesorero: seleccionar proveedor, completar formulario, validar datos y confirmar. | M14: OK | N14: 1. Refleja las expectativas del Presidente: registrar asistencia por QR o de forma manual y obtener un resumen con tasa de participación. | O14: NOK | P14: 1. La precondición referencia la asistencia sin usar el identificador correcto (escribe "CU-Registrar Asistencia" en lugar de CU-012). 2. No se indica quién puede ver el reporte generado automáticamente en el paso 15. | Q14: OK | R14: 1. Está alineado con los objetivos del sistema. 2. Refleja lo que realmente necesita el cliente. | S14: NOK | T14: 1. No esta acoplado mucho a los objetivos del sistema, ya que al tener prioridad media, no estan dando la suficiente importancia a un dato escencial del sistema | U14: OK | V14: 1. La edición de perfiles es una función lógica en cualquier gestión.
B15: 6 | C15: Consisten | E15: OK | F15: 1. El flujo diferencia correctamente aprobación y rechazo. 2. Las postcondiciones son coherentes con los pasos descritos. No hay contradicciones internas. | G15: OK | H15: 1. La información del proveedor mostrada en el paso 6 coincide con el perfil detallado del paso 10. 2. Flujo, postcondiciones y excepciones están alineados. | I15: OK | J15: 1. El costo total (paso 12) se calcula desde los subtotales por categoría (paso 11). 2. El semáforo (paso 14) depende directamente de esa comparación. La lógica es coherente de principio a fin. | K15: OK | L15: 1. La lista de cotizaciones actualizada en el paso 14 es la misma que consume "Evaluar Costos". 2. Las validaciones son consistentes con los campos del formulario del paso 7. | M15: OK | N15: 1. Los métodos QR y manual están diferenciados sin superponerse. 2. Las excepciones son coherentes con los errores esperados en cada método. | O15: OK | P15: 1. Las tres validaciones previas al cierre (pasos 7, 8 y 9) son independientes entre sí. 2. El bloqueo de edición del paso 13 es consecuente con el carácter irreversible del cierre. | Q15: OK | R15: 1. Documentación basada en modelos: Diagrama de Casos de Uso 2. Usa términos definidos previamente. | S15: OK | T15: 1. Documentación basada en modelos: Diagrama de Casos de Uso 2. Usa términos definidos previamente. | U15: OK | V15: 1. Mantiene la integridad con los datos creados en el CU-001..
B16: 7 | C16: Verifiable | E16: OK | F16: 1. Se puede probar que el sistema valide conflictos de fecha, cambie el estado a "Definido" y muestre el mensaje de confirmación. 2. Cada paso tiene un resultado observable. | G16: OK | H16: 1. Es posible verificar que el sistema muestre proveedores, aplique filtros, muestre el perfil completo y registre los candidatos seleccionados. | I16: OK | J16: 1. Las fórmulas de subtotales y costo total son verificables matemáticamente. 2. El semáforo y el cuadro comparativo son comprobables visualmente. | K16: OK | L16: 1. Las validaciones del formulario y el cálculo del costo por persona son comprobables con pruebas unitarias. 2. El registro en base de datos es verificable directamente. | M16: OK | N16: 1. Se puede probar la validación del QR, el marcado como Presente, el registro de hora y el cálculo de la tasa de participación con datos de prueba. | O16: OK | P16: 1. Las tres precondiciones del cierre, el bloqueo de edición y la habilitación de la liquidación son resultados observables y testeables. | Q16: OK | R16: 1. El cumplimiento de este requisito puede ser verificado. Los pasos están bien definidos, y puedes probar el flujo del ingreso de los datos y ek estado del socio. | S16: OK | T16: 1. Filtros por tipo de evento son testables. 2. Notificaciones en tiempos configurados son verificables. 3. Mensaje de "no hay eventos" es comprobable. | U16: OK | V16: 1. Basta con editar un campo y verificar que el cambio persista.
B17: 8 | C17: Realizable | E17: OK | F17: 1. Verificar conflictos de fecha es una consulta estándar a base de datos. 2. El cambio de estado y el registro de datos son operaciones CRUD convencionales. | G17: OK | H17: 1. El listado, filtrado y visualización de proveedores son funcionalidades estándar en sistemas web o móviles. 2. Asociar candidatos a un evento es una operación simple de base de datos. | I17: OK | J17: 1. Los cálculos de subtotales y costo total son operaciones aritméticas básicas. 2. El semáforo visual es un componente de UI estándar implementable con tecnologías actuales. | K17: OK | L17: 1. El formulario, las validaciones y el cálculo del costo por persona son funcionalidades básicas de cualquier sistema de gestión. | M17: OK | N17: 1. La lectura de QR es capacidad estándar en móviles modernos. 2. El registro manual con validación en lista de confirmados es una consulta y escritura simple en base de datos. | O17: OK | P17: 1. Actualizar estados, bloquear campos y habilitar un caso de uso posterior son operaciones técnicas estándar, realizables con las tecnologías actuales del proyecto. | Q17: OK | R17: 1. Funcionalidad tomada en cuenta dentro de la estimación del costo del proyecto ($1827) 2. No se ha desarrollado | S17: OK | T17: 1. Funcionalidad tomada en cuenta dentro de la estimación del costo del proyecto ($1827) 2. No se ha desarrollado | U17: OK | V17: Es una actualización (Update) básica en la base de datos.
B18: 9 | C18: Traceable | E18: OK | F18: 1. Identificador único: CU-008. 2. Referencia explícita a "CU Proponer Evento" como precondición. 3. Su origen está documentado en la entrevista con los stakeholders. | G18: OK | H18: 1. Identificador único: CU-009. 2. Vinculado como precondición de CU-011 y como extensión posible de CU-010. 3. Punto de acceso claro desde el módulo "Definir Evento". | I18: NOK | J18: 1. En el PDF aparece como "CU-010 Evaluar Costos", pero en la tabla de ejemplo de otros compañeros figura como "CU-010 Ingresar Proveedor". 2. La inconsistencia en la nomenclatura entre documentos afecta la trazabilidad. | K18: OK | L18: 1. Identificador único: CU-011. 2. Referencia CU-009 como insumo previo y su resultado alimenta directamente CU-010. 3. Trazabilidad clara dentro del flujo. | M18: OK | N18: 1. Identificador único: CU-012. 2. Referencia el estado "Difundido" del evento y vincula su resultado con CU-013. 3. Correctamente ubicado en el módulo "Ejecutar Evento". | O18: NOK | P18: 1. Identificador: CU-013. 2. La precondición referencia la asistencia como "CU-Registrar Asistencia" en lugar de CU-012, rompiendo la trazabilidad formal entre requisitos. | Q18: OK | R18: 1. No se refleja en claro las relaciones con lode demás requisitos q deben estar asociados | S18: OK | T18: Vinculado al requerimiento de control de acceso por niveles. | U18: OK | V18: Se vincula a la gestión continua de la membresía del club.
B19: 10 | C19: Complete | E19: NOK | F19: 1. El paso 11 dice "el software registra la programación del evento EN DONDE", lo que evidencia un campo incompleto. 2. No se especifica en qué módulo o tabla se almacena la información. | G19: OK | H19: 1. Cubre todos los aspectos: acceso, listado, filtros, perfil del proveedor, selección de candidatos y registro en el sistema. 2. Las excepciones contemplan todos los errores posibles. | I19: OK | J19: 1. Abarca recuperación de cotizaciones, comparación, cálculo de subtotales y costo total, validación presupuestaria, semáforo y selección final. | K19: OK | L19: 1. Cubre selección de proveedor, formulario completo, validaciones, cálculo del costo por persona y actualización de la lista. 2. Las excepciones son exhaustivas. | M19: OK | N19: 1. Trata los dos métodos de registro (QR y manual), validación de identidad, marcado de asistencia, cálculo de tasa de participación y resumen final. | O19: NOK | P19: 1. El paso 15 menciona un reporte generado automáticamente, pero no especifica su formato ni quién puede accederlo. 2. Queda sin definir si ese reporte está disponible para el proceso de liquidación. | Q19: NOK | R19: 1. Falta el flujo de error si la cédula ya está registrada o es inválida | S19: NOK | T19: 1.No aclara si un socio puede tener dos roles al mismo tiempo. | U19: NOK | V19: 1. No define qué campos no se pueden editar (ej. la cédula.
B20: 11 | C20: Understandability | E20: OK | F20: 1. Usa terminología clara del dominio (evento, propuesta, Presidente). 2. El flujo es secuencial y comprensible sin conocimiento técnico. | G20: OK | H20: 1. Lenguaje accesible y directo. 2. Términos como "candidatos", "filtros" y "perfil" son comprensibles para cualquier interesado. | I20: OK | J20: 1. La estructura general es clara. 2. Las fórmulas del paso 11 pueden resultar técnicas para un lector no especializado; se recomienda acompañarlas de un ejemplo. | K20: OK | L20: 1. Flujo claro para cualquier lector. 2. El formulario está bien detallado y el cálculo del costo por persona es fácil de entender. | M20: OK | N20: 1. Distingue claramente los dos métodos de registro. 2. Los conceptos "Presente" y "Presente (manual)" son autoexplicativos. | O20: OK | P20: 1. Flujo bien organizado con validaciones previas claras. 2. No contiene lenguaje técnico que dificulte la comprensión. | Q20: OK | R20: 1. Se involucra al cliente 2. Existe glosario de términos | S20: OK | T20: 1. Se involucra al cliente 2. Existe glosario de términos | U20: OK | V20: 1. Se involucra al cliente 2. Existe glosario de términos

Sheet MODELO LISTA DE COMPROBACION 1
A1: SISTEMA: | C1: Sistema de planificación y seguimiento de eventos sociales y deportivos del Club de Suboficiales Retirados (EVENTUAL)
A2: FECHA: | C2: 46157
A3: AUTOR: | C3: Alex Cuzco
A4: REQUERIMIENTOS EVALUADOS : | C4: CU-006: Registrar Gastos del Evento
A6: CONTENIDO
A7: No. | B7: Pregunta | C7: SI | D7: NO
A8: 1 | B8: Todos los requerimientos relevantes se han documentado? | C8: X
A9: 2 | B9: Se han implementado las funciones requeridas? | C9: X
A10: 3 | B10: Existe algún mecanismo que permita seguir el impacto de dicho requerimiento a lo largo del resto de las actividades del ciclo productivo.? | D10: X
A11: 4 | B11: El origen de cada requerimento individual está claro ? | C11: X
A12: 5 | B12: Que tan facil es devolverse a los requerimientos? | C12: X
A13: 6 | B13: Los requerimientos reflejan las necesidades y deseos del cliente? | C13: X
A14: 7 | B14: No hay contradicciones entre los requerimientos? | C14: X
A15: 8 | B15: El requerimiento que se esta especificando contribuye a alcanzar un objetivo definido ? | C15: X
A16: 9 | B16: Existe un proceso acotado (en plazo y presupuesto) que permita determinar que el sistema construido satisface lo descrito en el propio requerimiento? | C16: X
A17: SUMATORIA: | C17: =COUNTA('MODELO LISTA DE COMPROBACION 1'!$C$8:$C$16) -> 8 | D17: =COUNTA('MODELO LISTA DE COMPROBACION 1'!$D$8:$D$16) -> 1
A18: PORCENTAJE : | C18: =C17/9 -> 0.88888889 | D18: =D17/9 -> 0.11111111
A20: DOCUMENTACIÓN
A21: No. | B21: Pregunta | C21: SI | D21: NO
A22: 1 | B22: Aplica un estandar para la documetación de requerimiento? | C22: X
A23: 2 | B23: Cumple con la estructura definida por el estandar? | C23: X
A24: 3 | B24: Utiliza un Glosario de términos normalizado? | C24: X
A25: 4 | B25: Los requerimientos Funcionales estan sujetos a una única interpretación? | C25: X
A26: 5 | B26: El modelo aplicado cumple con la sintaxis? | C26: X
A27: SUMATORIA: | C27: =COUNTA('MODELO LISTA DE COMPROBACION 1'!$C$22:$C$26) -> 5 | D27: =COUNTA('MODELO LISTA DE COMPROBACION 1'!$D$22:$D$26) -> 0
A28: PORCENTAJE : | C28: =C27/5 -> 1 | D28: =D27/5 -> 0
A30: NIVEL DE ACUERDO
A31: No. | B31: Pregunta | C31: SI | D31: NO
A32: 1 | B32: Todos los requerimientos han sido acordados con todos los interesados? | C32: X
A33: 2 | B33: Todos los requerimientos modificados han sido acordados por todos los implicados? | C33: X
A34: 3 | B34: Han sido resueltos todos los conflictos conocidos respectos de los requerimientos? | C34: X
A35: SUMATORIA: | C35: =COUNTA('MODELO LISTA DE COMPROBACION 1'!$C$32:$C$34) -> 3 | D35: =COUNTA('MODELO LISTA DE COMPROBACION 1'!$D$32:$D$34) -> 0
A36: PORCENTAJE : | C36: =C35/3 -> 1 | D36: =D35/3 -> 0
B40: RESUMEN
B41: CONTENIDO | C41: 89
B42: DOCUMENTACIÓN | C42: 100
B43: NIVEL DE ACUERDO | C43: 100

Sheet MODELO LISTA DE COMPROBACION 2
A1: SISTEMA: | C1: Sistema de planificación y seguimiento de eventos sociales y deportivos del Club de Suboficiales Retirados (EVENTUAL)
A2: FECHA: | C2: 46159
A3: AUTOR: | C3: Alex Cuzco
A4: REQUERIMIENTOS EVALUADOS : | C4: CU-007: Registrar Aportes Económicos
A6: CONTENIDO
A7: No. | B7: Pregunta | C7: SI | D7: NO
A8: 1 | B8: Todos los requerimientos relevantes se han documentado? | C8: X
A9: 2 | B9: Se han implementado las funciones requeridas? | C9: X
A10: 3 | B10: Existe algún mecanismo que permita seguir el impacto de dicho requerimiento a lo largo del resto de las actividades del ciclo productivo.? | C10: X
A11: 4 | B11: El origen de cada requerimento individual está claro ? | C11: X
A12: 5 | B12: Que tan facil es devolverse a los requerimientos? | C12: X
A13: 6 | B13: Los requerimientos reflejan las necesidades y deseos del cliente? | C13: X
A14: 7 | B14: No hay contradicciones entre los requerimientos? | C14: X
A15: 8 | B15: El requerimiento que se esta especificando contribuye a alcanzar un objetivo definido ? | C15: X
A16: 9 | B16: Existe un proceso acotado (en plazo y presupuesto) que permita determinar que el sistema construido satisface lo descrito en el propio requerimiento? | C16: X
A17: SUMATORIA: | C17: =COUNTA('MODELO LISTA DE COMPROBACION 2'!$C$8:$C$16) -> 9 | D17: =COUNTA('MODELO LISTA DE COMPROBACION 2'!$D$8:$D$16) -> 0
A18: PORCENTAJE : | C18: =C17/9 -> 1 | D18: =D17/9 -> 0
A20: DOCUMENTACIÓN
A21: No. | B21: Pregunta | C21: SI | D21: NO
A22: 1 | B22: Aplica un estandar para la documetación de requerimiento? | C22: X
A23: 2 | B23: Cumple con la estructura definida por el estandar? | C23: X
A24: 3 | B24: Utiliza un Glosario de términos normalizado? | C24: X
A25: 4 | B25: Los requerimientos Funcionales estan sujetos a una única interpretación? | D25: X
A26: 5 | B26: El modelo aplicado cumple con la sintaxis? | C26: X
A27: SUMATORIA: | C27: 4 | D27: 1
A28: PORCENTAJE : | C28: =C27/5 -> 0.8 | D28: =D27/5 -> 0.2
A30: NIVEL DE ACUERDO
A31: No. | B31: Pregunta | C31: SI | D31: NO
A32: 1 | B32: Todos los requerimientos han sido acordados con todos los interesados? | C32: X
A33: 2 | B33: Todos los requerimientos modificados han sido acordados por todos los implicados? | C33: X
A34: 3 | B34: Han sido resueltos todos los conflictos conocidos respectos de los requerimientos? | C34: X
A35: SUMATORIA: | C35: 3 | D35: 1
A36: PORCENTAJE : | C36: =C35/3 -> 1 | D36: =D35/3 -> 0.33333333
B40: RESUMEN
B41: CONTENIDO | C41: 100
B42: DOCUMENTACIÓN | C42: 80
B43: NIVEL DE ACUERDO | C43: 100

Sheet MODELO LISTA DE COMPROBACION 3
A1: SISTEMA: | C1: Sistema de planificación y seguimiento de eventos sociales y deportivos del Club de Suboficiales Retirados (EVENTUAL)
A2: FECHA: | C2: 46159
A3: AUTOR: | C3: Alex Cuzco
A4: REQUERIMIENTOS EVALUADOS : | C4: CU-008 Registrar Evento
A6: CONTENIDO
A7: No. | B7: Pregunta | C7: SI | D7: NO
A8: 1 | B8: Todos los requerimientos relevantes se han documentado? | C8: X
A9: 2 | B9: Se han implementado las funciones requeridas? | C9: X
A10: 3 | B10: Existe algún mecanismo que permita seguir el impacto de dicho requerimiento a lo largo del resto de las actividades del ciclo productivo.? | D10: X
A11: 4 | B11: El origen de cada requerimento individual está claro ? | C11: X
A12: 5 | B12: Que tan facil es devolverse a los requerimientos? | C12: X
A13: 6 | B13: Los requerimientos reflejan las necesidades y deseos del cliente? | C13: X
A14: 7 | B14: No hay contradicciones entre los requerimientos? | D14: X
A15: 8 | B15: El requerimiento que se esta especificando contribuye a alcanzar un objetivo definido ? | C15: X
A16: 9 | B16: Existe un proceso acotado (en plazo y presupuesto) que permita determinar que el sistema construido satisface lo descrito en el propio requerimiento? | C16: X
A17: SUMATORIA: | C17: 7 | D17: 2
A18: PORCENTAJE : | C18: =C17/9 -> 0.77777778 | D18: =D17/9 -> 0.22222222
A20: DOCUMENTACIÓN
A21: No. | B21: Pregunta | C21: SI | D21: NO
A22: 1 | B22: Aplica un estandar para la documetación de requerimiento? | C22: X
A23: 2 | B23: Cumple con la estructura definida por el estandar? | C23: X
A24: 3 | B24: Utiliza un Glosario de términos normalizado? | C24: X
A25: 4 | B25: Los requerimientos Funcionales estan sujetos a una única interpretación? | D25: X
A26: 5 | B26: El modelo aplicado cumple con la sintaxis? | C26: X
A27: SUMATORIA: | C27: 4 | D27: 1
A28: PORCENTAJE : | C28: =C27/5 -> 0.8 | D28: =D27/5 -> 0.2
A30: NIVEL DE ACUERDO
A31: No. | B31: Pregunta | C31: SI | D31: NO
A32: 1 | B32: Todos los requerimientos han sido acordados con todos los interesados? | C32: X
A33: 2 | B33: Todos los requerimientos modificados han sido acordados por todos los implicados? | C33: X
A34: 3 | B34: Han sido resueltos todos los conflictos conocidos respectos de los requerimientos? | C34: X
A35: SUMATORIA: | C35: 3 | D35: 0
A36: PORCENTAJE : | C36: =C35/3 -> 1 | D36: =D35/3 -> 0
B40: RESUMEN
B41: CONTENIDO | C41: 78
B42: DOCUMENTACIÓN | C42: 80
B43: NIVEL DE ACUERDO | C43: 100

Sheet MODELO LISTA DE COMPROBACION 4
A1: SISTEMA: | C1: Sistema de planificación y seguimiento de eventos sociales y deportivos del Club de Suboficiales Retirados (EVENTUAL)
A2: FECHA: | C2: 46160
A3: AUTOR: | C3: Alex Cuzco
A4: REQUERIMIENTOS EVALUADOS : | C4: CU-009 Difundir Información del Evento
A6: CONTENIDO
A7: No. | B7: Pregunta | C7: SI | D7: NO
A8: 1 | B8: Todos los requerimientos relevantes se han documentado? | C8: X
A9: 2 | B9: Se han implementado las funciones requeridas? | C9: X
A10: 3 | B10: Existe algún mecanismo que permita seguir el impacto de dicho requerimiento a lo largo del resto de las actividades del ciclo productivo.? | D10: X
A11: 4 | B11: El origen de cada requerimento individual está claro ? | C11: X
A12: 5 | B12: Que tan facil es devolverse a los requerimientos? | C12: X
A13: 6 | B13: Los requerimientos reflejan las necesidades y deseos del cliente? | C13: X
A14: 7 | B14: No hay contradicciones entre los requerimientos? | D14: X
A15: 8 | B15: El requerimiento que se esta especificando contribuye a alcanzar un objetivo definido ? | C15: X
A16: 9 | B16: Existe un proceso acotado (en plazo y presupuesto) que permita determinar que el sistema construido satisface lo descrito en el propio requerimiento? | C16: X
A17: SUMATORIA: | C17: 7 | D17: 2
A18: PORCENTAJE : | C18: =C17/9 -> 0.77777778 | D18: =D17/9 -> 0.22222222
A20: DOCUMENTACIÓN
A21: No. | B21: Pregunta | C21: SI | D21: NO
A22: 1 | B22: Aplica un estandar para la documetación de requerimiento? | C22: X
A23: 2 | B23: Cumple con la estructura definida por el estandar? | C23: X
A24: 3 | B24: Utiliza un Glosario de términos normalizado? | C24: X
A25: 4 | B25: Los requerimientos Funcionales estan sujetos a una única interpretación? | D25: X
A26: 5 | B26: El modelo aplicado cumple con la sintaxis? | C26: X
A27: SUMATORIA: | C27: 4 | D27: 1
A28: PORCENTAJE : | C28: =C27/5 -> 0.8 | D28: =D27/5 -> 0.2
A30: NIVEL DE ACUERDO
A31: No. | B31: Pregunta | C31: SI | D31: NO
A32: 1 | B32: Todos los requerimientos han sido acordados con todos los interesados? | C32: X
A33: 2 | B33: Todos los requerimientos modificados han sido acordados por todos los implicados? | C33: X
A34: 3 | B34: Han sido resueltos todos los conflictos conocidos respectos de los requerimientos? | C34: X
A35: SUMATORIA: | C35: 3 | D35: 0
A36: PORCENTAJE : | C36: =C35/3 -> 1 | D36: =D35/3 -> 0
B40: RESUMEN
B41: CONTENIDO | C41: 78
B42: DOCUMENTACIÓN | C42: 80
B43: NIVEL DE ACUERDO | C43: 100

Sheet MODELO LISTA DE COMPROBACION 5
A1: SISTEMA: | C1: Sistema de planificación y seguimiento de eventos sociales y deportivos del Club de Suboficiales Retirados (EVENTUAL)
A2: FECHA: | C2: 46160
A3: AUTOR: | C3: Pablo Domínguez
A4: REQUERIMIENTOS EVALUADOS : | C4: CU-010 Ingresar Proveedor
A6: CONTENIDO
A7: No. | B7: Pregunta | C7: SI | D7: NO
A8: 1 | B8: Todos los requerimientos relevantes se han documentado? | C8: X
A9: 2 | B9: Se han implementado las funciones requeridas? | C9: X
A10: 3 | B10: Existe algún mecanismo que permita seguir el impacto de dicho requerimiento a lo largo del resto de las actividades del ciclo productivo.? | D10: X
A11: 4 | B11: El origen de cada requerimento individual está claro ? | C11: X
A12: 5 | B12: Que tan facil es devolverse a los requerimientos? | C12: X
A13: 6 | B13: Los requerimientos reflejan las necesidades y deseos del cliente? | C13: X
A14: 7 | B14: No hay contradicciones entre los requerimientos? | D14: X
A15: 8 | B15: El requerimiento que se esta especificando contribuye a alcanzar un objetivo definido ? | C15: X
A16: 9 | B16: Existe un proceso acotado (en plazo y presupuesto) que permita determinar que el sistema construido satisface lo descrito en el propio requerimiento? | C16: X
A17: SUMATORIA: | C17: 7 | D17: 2
A18: PORCENTAJE : | C18: =C17/9 -> 0.77777778 | D18: =D17/9 -> 0.22222222
A20: DOCUMENTACIÓN
A21: No. | B21: Pregunta | C21: SI | D21: NO
A22: 1 | B22: Aplica un estandar para la documetación de requerimiento? | C22: X
A23: 2 | B23: Cumple con la estructura definida por el estandar? | C23: X
A24: 3 | B24: Utiliza un Glosario de términos normalizado? | C24: X
A25: 4 | B25: Los requerimientos Funcionales estan sujetos a una única interpretación? | D25: X
A26: 5 | B26: El modelo aplicado cumple con la sintaxis? | C26: X
A27: SUMATORIA: | C27: 4 | D27: 1
A28: PORCENTAJE : | C28: =C27/5 -> 0.8 | D28: =D27/5 -> 0.2
A30: NIVEL DE ACUERDO
A31: No. | B31: Pregunta | C31: SI | D31: NO
A32: 1 | B32: Todos los requerimientos han sido acordados con todos los interesados? | C32: X
A33: 2 | B33: Todos los requerimientos modificados han sido acordados por todos los implicados? | C33: X
A34: 3 | B34: Han sido resueltos todos los conflictos conocidos respectos de los requerimientos? | D34: X
A35: SUMATORIA: | C35: 2 | D35: 1
A36: PORCENTAJE : | C36: =C35/3 -> 0.66666667 | D36: =D35/3 -> 0.33333333
B40: RESUMEN
B41: CONTENIDO | C41: 78
B42: DOCUMENTACIÓN | C42: 80
B43: NIVEL DE ACUERDO | C43: 67

Sheet MODELO LISTA DE COMPROBACION 6
A1: SISTEMA: | C1: Sistema de planificación y seguimiento de eventos sociales y deportivos del Club de Suboficiales Retirados (EVENTUAL)
A2: FECHA: | C2: 46160
A3: AUTOR: | C3: Pablo Domínguez
A4: REQUERIMIENTOS EVALUADOS : | C4: CU-011 Definir Evento
A6: CONTENIDO
A7: No. | B7: Pregunta | C7: SI | D7: NO
A8: 1 | B8: Todos los requerimientos relevantes se han documentado? | C8: X
A9: 2 | B9: Se han implementado las funciones requeridas? | C9: X
A10: 3 | B10: Existe algún mecanismo que permita seguir el impacto de dicho requerimiento a lo largo del resto de las actividades del ciclo productivo.? | D10: X
A11: 4 | B11: El origen de cada requerimento individual está claro ? | C11: X
A12: 5 | B12: Que tan facil es devolverse a los requerimientos? | C12: X
A13: 6 | B13: Los requerimientos reflejan las necesidades y deseos del cliente? | C13: X
A14: 7 | B14: No hay contradicciones entre los requerimientos? | D14: X
A15: 8 | B15: El requerimiento que se esta especificando contribuye a alcanzar un objetivo definido ? | C15: X
A16: 9 | B16: Existe un proceso acotado (en plazo y presupuesto) que permita determinar que el sistema construido satisface lo descrito en el propio requerimiento? | C16: X
A17: SUMATORIA: | C17: 7 | D17: 2
A18: PORCENTAJE : | C18: =C17/9 -> 0.77777778 | D18: =D17/9 -> 0.22222222
A20: DOCUMENTACIÓN
A21: No. | B21: Pregunta | C21: SI | D21: NO
A22: 1 | B22: Aplica un estandar para la documetación de requerimiento? | C22: X
A23: 2 | B23: Cumple con la estructura definida por el estandar? | C23: X
A24: 3 | B24: Utiliza un Glosario de términos normalizado? | C24: X
A25: 4 | B25: Los requerimientos Funcionales estan sujetos a una única interpretación? | D25: X
A26: 5 | B26: El modelo aplicado cumple con la sintaxis? | C26: X
A27: SUMATORIA: | C27: 4 | D27: 1
A28: PORCENTAJE : | C28: =C27/5 -> 0.8 | D28: =D27/5 -> 0.2
A30: NIVEL DE ACUERDO
A31: No. | B31: Pregunta | C31: SI | D31: NO
A32: 1 | B32: Todos los requerimientos han sido acordados con todos los interesados? | C32: X
A33: 2 | B33: Todos los requerimientos modificados han sido acordados por todos los implicados? | C33: X
A34: 3 | B34: Han sido resueltos todos los conflictos conocidos respectos de los requerimientos? | D34: X
A35: SUMATORIA: | C35: 2 | D35: 1
A36: PORCENTAJE : | C36: =C35/3 -> 0.66666667 | D36: =D35/3 -> 0.33333333
B40: RESUMEN
B41: CONTENIDO | C41: 78
B42: DOCUMENTACIÓN | C42: 80
B43: NIVEL DE ACUERDO | C43: 67

Sheet MODELO LISTA DE COMPROBACION 7
A1: SISTEMA: | C1: Sistema de planificación y seguimiento de eventos sociales y deportivos del Club de Suboficiales Retirados (EVENTUAL)
A2: FECHA: | C2: 46160
A3: AUTOR: | C3: Pablo Domínguez
A4: REQUERIMIENTOS EVALUADOS : | C4: CU-012 Ejecutar Evento
A6: CONTENIDO
A7: No. | B7: Pregunta | C7: SI | D7: NO
A8: 1 | B8: Todos los requerimientos relevantes se han documentado? | C8: X
A9: 2 | B9: Se han implementado las funciones requeridas? | C9: X
A10: 3 | B10: Existe algún mecanismo que permita seguir el impacto de dicho requerimiento a lo largo del resto de las actividades del ciclo productivo.? | D10: X
A11: 4 | B11: El origen de cada requerimento individual está claro ? | C11: X
A12: 5 | B12: Que tan facil es devolverse a los requerimientos? | C12: X
A13: 6 | B13: Los requerimientos reflejan las necesidades y deseos del cliente? | C13: X
A14: 7 | B14: No hay contradicciones entre los requerimientos? | D14: X
A15: 8 | B15: El requerimiento que se esta especificando contribuye a alcanzar un objetivo definido ? | C15: X
A16: 9 | B16: Existe un proceso acotado (en plazo y presupuesto) que permita determinar que el sistema construido satisface lo descrito en el propio requerimiento? | C16: X
A17: SUMATORIA: | C17: 7 | D17: 2
A18: PORCENTAJE : | C18: =C17/9 -> 0.77777778 | D18: =D17/9 -> 0.22222222
A20: DOCUMENTACIÓN
A21: No. | B21: Pregunta | C21: SI | D21: NO
A22: 1 | B22: Aplica un estandar para la documetación de requerimiento? | C22: X
A23: 2 | B23: Cumple con la estructura definida por el estandar? | C23: X
A24: 3 | B24: Utiliza un Glosario de términos normalizado? | C24: X
A25: 4 | B25: Los requerimientos Funcionales estan sujetos a una única interpretación? | D25: X
A26: 5 | B26: El modelo aplicado cumple con la sintaxis? | C26: X
A27: SUMATORIA: | C27: 4 | D27: 1
A28: PORCENTAJE : | C28: =C27/5 -> 0.8 | D28: =D27/5 -> 0.2
A30: NIVEL DE ACUERDO
A31: No. | B31: Pregunta | C31: SI | D31: NO
A32: 1 | B32: Todos los requerimientos han sido acordados con todos los interesados? | C32: X
A33: 2 | B33: Todos los requerimientos modificados han sido acordados por todos los implicados? | C33: X
A34: 3 | B34: Han sido resueltos todos los conflictos conocidos respectos de los requerimientos? | D34: X
A35: SUMATORIA: | C35: 2 | D35: 1
A36: PORCENTAJE : | C36: =C35/3 -> 0.66666667 | D36: =D35/3 -> 0.33333333
B40: RESUMEN
B41: CONTENIDO | C41: 78
B42: DOCUMENTACIÓN | C42: 80
B43: NIVEL DE ACUERDO | C43: 67

Sheet MODELO LISTA DE COMPROBACION 8
A1: SISTEMA: | C1: Sistema de planificación y seguimiento de eventos sociales y deportivos del Club de Suboficiales Retirados (EVENTUAL)
A2: FECHA: | C2: 46160
A3: AUTOR: | C3: Pablo Domínguez
A4: REQUERIMIENTOS EVALUADOS : | C4: CU-013 Generar Reportes
A6: CONTENIDO
A7: No. | B7: Pregunta | C7: SI | D7: NO
A8: 1 | B8: Todos los requerimientos relevantes se han documentado? | C8: X
A9: 2 | B9: Se han implementado las funciones requeridas? | D9: X
A10: 3 | B10: Existe algún mecanismo que permita seguir el impacto de dicho requerimiento a lo largo del resto de las actividades del ciclo productivo.? | D10: X
A11: 4 | B11: El origen de cada requerimento individual está claro ? | D11: X
A12: 5 | B12: Que tan facil es devolverse a los requerimientos? | C12: X
A13: 6 | B13: Los requerimientos reflejan las necesidades y deseos del cliente? | C13: X
A14: 7 | B14: No hay contradicciones entre los requerimientos? | D14: X
A15: 8 | B15: El requerimiento que se esta especificando contribuye a alcanzar un objetivo definido ? | C15: X
A16: 9 | B16: Existe un proceso acotado (en plazo y presupuesto) que permita determinar que el sistema construido satisface lo descrito en el propio requerimiento? | C16: X
A17: SUMATORIA: | C17: 5 | D17: 4
A18: PORCENTAJE : | C18: =C17/9 -> 0.55555556 | D18: =D17/9 -> 0.44444444
A20: DOCUMENTACIÓN
A21: No. | B21: Pregunta | C21: SI | D21: NO
A22: 1 | B22: Aplica un estandar para la documetación de requerimiento? | C22: X
A23: 2 | B23: Cumple con la estructura definida por el estandar? | C23: X
A24: 3 | B24: Utiliza un Glosario de términos normalizado? | C24: X
A25: 4 | B25: Los requerimientos Funcionales estan sujetos a una única interpretación? | D25: X
A26: 5 | B26: El modelo aplicado cumple con la sintaxis? | C26: X
A27: SUMATORIA: | C27: 4 | D27: 1
A28: PORCENTAJE : | C28: =C27/5 -> 0.8 | D28: =D27/5 -> 0.2
A30: NIVEL DE ACUERDO
A31: No. | B31: Pregunta | C31: SI | D31: NO
A32: 1 | B32: Todos los requerimientos han sido acordados con todos los interesados? | C32: X
A33: 2 | B33: Todos los requerimientos modificados han sido acordados por todos los implicados? | C33: X
A34: 3 | B34: Han sido resueltos todos los conflictos conocidos respectos de los requerimientos? | D34: X
A35: SUMATORIA: | C35: 2 | D35: 1
A36: PORCENTAJE : | C36: =C35/3 -> 0.66666667 | D36: =D35/3 -> 0.33333333
B40: RESUMEN
B41: CONTENIDO | C41: 56
B42: DOCUMENTACIÓN | C42: 80
B43: NIVEL DE ACUERDO | C43: 67

Sheet RECOMENDACIONES
A2: CU-006: Registrar Gastos del Evento
A3: PREGUNTA | B3: RECOMENDACIÓN
A4: ¿Las categorías de gasto (alimentación, transporte, decoración, etc.) son una lista fija predefinida en el sistema o el Tesorero puede ingresar texto libre? ¿Y cuál es el formato válido para el campo monto (número entero, decimal con dos cifras, separador de miles)? | B4: En el paso 3, especificar el tipo de dato y restricciones de cada campo (ej. "monto: decimal positivo con 2 cifras") y definir si las categorías son una lista fija. Agregar en las excepciones el mensaje exacto del sistema para cada error.
A6: CU-007: Registrar Aportes Económicos
A7: PREGUNTA | B7: RECOMENDACIÓN
A8: ¿El aporte económico de un socio afecta directamente el presupuesto del evento, se emite algún comprobante digital al validar el pago, y qué ocurre si el monto supera la cuota estándar requerida? | B8: Agregar en la secuencia normal si el aporte impacta el presupuesto del evento, incluir un paso para la generación del comprobante digital y definir en las excepciones el flujo exacto cuando el monto supera la cuota estándar.
A10: CU-008 Registrar Evento
A11: PREGUNTA | B11: RECOMENDACIÓN
A12: ¿Qué cronograma específico sigue el sistema para programar las notificaciones al registrar el evento? | B12: Sería recomendable reemplazar "según el cronograma definido" en el paso 10 por los tiempos exactos de notificación.
A13: ¿De qué reunión o entrevista surgió este requerimiento y qué relación tiene con los requisitos no funcionales del sistema? | B13: Agregar el origen del requerimiento y sus vínculos explícitos con NF-04 y NF-05.
A14: ¿Qué ocurre si el Presidente intenta registrar el evento sin haber completado la evaluación de costos o sube documentos duplicados? | B14: Incluir excepción para documentos duplicados y definir tipos y tamaños máximos de archivos permitidos.
A16: CU-009 Difundir Información del Evento
A17: PREGUNTA | B17: RECOMENDACIÓN
A18: ¿Qué condición exacta determina que la configuración de difusión es "coherente" con la fecha del evento? | B18: Reemplazar "coherente" por una regla concreta medible (ej. "la fecha de envío debe ser mínimo 15 días antes del evento").
A19: ¿De qué fuente surgió este requerimiento y cómo se relaciona con los requisitos de conectividad y rendimiento del sistema? | B19: Agregar el origen del requerimiento y sus vínculos con NF-03 y NF-06.
A20: ¿Qué ocurre si un socio no tiene WhatsApp configurado y existe un límite de caracteres para el mensaje personalizable? | B20: Agregar excepción para socios sin WhatsApp, error al cargar la plantilla institucional y definir el límite máximo de caracteres del mensaje.
A22: CU-010 Ingresar Proveedor
A23: PREGUNTA | B23: RECOMENDACIÓN
A24: ¿Bajo qué escala se asigna la calificación inicial del proveedor? | B24: Definir la escala con valores exactos (ej. "1 a 5 estrellas") en el paso 8.
A25: ¿El caso de uso aplica solo para proveedores de viajes terrestres o para cualquier tipo de servicio? | B25: Corregir la descripción para que refleje todos los tipos de proveedores que maneja el sistema.
A26: ¿Por qué la descripción menciona viajes terrestres si el formulario incluye categorías como alimentación, sonido y decoración? | B26: Unificar la descripción del caso de uso con las categorías reales del formulario para eliminar la contradicción.
A27: ¿Qué campos del formulario son obligatorios, cuál es el formato válido del email y teléfono, y cómo se validan? | B27: Especificar campos obligatorios y opcionales, agregar validaciones de formato para email y teléfono en las excepciones.
A28: ¿Bajo qué escala se asigna la calificación inicial del proveedor? | B28: Definir la escala con valores exactos (ej. "1 a 5 estrellas") en el paso 8.
A30: CU-011 Definir Evento
A31: PREGUNTA | B31: RECOMENDACIÓN
A32: ¿Qué reunión o entrevista originó este requerimiento y qué relación tiene con los requisitos no funcionales del sistema? | B32: Agregar el origen del requerimiento con referencia explícita a la entrevista realizada y sus vínculos con los NF correspondientes (ej. NF-01, NF-02).
A33: ¿En qué módulo o tabla del sistema se almacena la programación del evento? | B33: Completar el paso 11 indicando el módulo o tabla de destino. Mientras no se defina, el requisito queda incompleto e iimplementable.
A34: ¿El identificador CU-010 corresponde a "Evaluar Costos" o a "Ingresar Proveedor"? Hay dos documentos que asignan ese mismo ID a casos de uso distintos. | B34: Unificar la numeración entre el equipo. Asignar un identificador único a cada caso de uso y actualizar todas las referencias en el documento.
A35: ¿Qué ocurre en Evaluar Costos si el usuario marca una sola cotización como preferida? El flujo solo describe el caso de varias. | B35: Agregar en la secuencia normal o en las excepciones el comportamiento del sistema cuando se selecciona únicamente una cotización preferida.
A36: ¿El semáforo visual de Evaluar Costos se muestra siempre o solo cuando hay cotizaciones preferidas seleccionadas? | B36: Especificar la condición exacta que activa el semáforo. Una regla concreta evita interpretaciones distintas durante el desarrollo.
A37: ¿La precondición de CU-011 hace referencia a "RF 10 INGRESAR PROVEEDORES", pero ese nombre no existe en el documento. ¿A qué caso de uso corresponde realmente? | B37: Reemplazar "RF 10 INGRESAR PROVEEDORES" por el identificador correcto (CU-009 Consultar Proveedores) y verificar todas las referencias cruzadas del módulo.
A39: CU-012 Ejecutar Evento
A40: PREGUNTA | B40: RECOMENDACIÓN
A41: ¿Qué reunión o entrevista originó este requerimiento y qué relación tiene con los requisitos no funcionales del sistema? | B41: Agregar el origen del requerimiento con referencia explícita a la entrevista realizada y sus vínculos con los NF correspondientes.
A42: La precondición de CU-013 dice "CU-Registrar Asistencia" sin número. ¿Por qué no se usa el identificador CU-012? | B42: Reemplazar la referencia incompleta por CU-012. Todas las precondiciones deben usar el identificador oficial para mantener la trazabilidad.
A43: ¿Quién puede ver el reporte de asistencia generado automáticamente en el paso 15 de CU-013? ¿Está disponible para la liquidación? | B43: Especificar el actor que accede al reporte y si su resultado queda disponible como insumo para el caso de uso de liquidación financiera.
A44: ¿Qué formato tiene el reporte de asistencia del paso 15 de CU-013? ¿PDF, Excel, pantalla? | B44: Definir el formato de salida del reporte. Sin eso, el requisito es incompleto y cada desarrollador puede interpretarlo de forma distinta.
A45: ¿Qué ocurre si el Presidente intenta cerrar el evento sin haber registrado ningún gasto? ¿El sistema bloquea o advierte? | B45: Agregar una excepción específica para ese caso, diferenciando entre bloqueo total o advertencia con opción de continuar.
A47: CU-013 Generar reportes
A48: PREGUNTA | B48: RECOMENDACIÓN
...
